<!-- https://mymodelrobot.appspot.com/5629499534213120 -->
<robot xmlns:xacro="http://www.ros.org/wiki/xacro" name="AlexaBot">
    
    <!-- Link definitions -->
    <link name="head">
        <visual>
            <!--<geometry><sphere radius="0.1"/></geometry>-->
            <geometry><box size="0.2 0.2 0.2"/></geometry>
            <origin xyz="0 0 0" rpy="0 0 0"/>
        </visual>
    </link>

    <joint name="neckZ" type="revolute">
        <parent link="torso"/>
        <child link="head"/>
        <origin xyz="0 0 0.0" rpy="0 0 0"/>
        <axis xyz="0 0 1"/>
    </joint>

    <link name="center">
        <visual>
            <geometry><box size="0.15 0.25 0.34"/></geometry>
            <origin xyz="0 0 0" rpy="0 0 0"/>
        </visual>
    </link>

    <joint name="waistY" type="revolute">
        <parent link="center"/>
        <child link="torso"/>
        <origin xyz="0 0 0.17" rpy="0 0 0"/>
        <axis xyz="0 1 0"/>
    </joint>

    <joint name="waistZ" type="revolute">
        <parent link="center"/>
        <child link="torso"/>
        <origin xyz="0 0 0.17" rpy="0 0 0"/>
        <axis xyz="0 0 1"/>
    </joint>

    <link name="torso">
        <visual>
            <geometry><box size="0.2 0.3 0.5"/></geometry>
            <origin xyz="0 0 0.25" rpy="0 0 0"/>
        </visual>
    </link>

    <!-- Left arm -->
    <!--<joint name="shoulderLY" type="revolute">
        <parent link="torso"/>
        <child link="armL_upper"/>
        <origin xyz="0 0.2 0.25" rpy="0 0 0"/>
        <axis xyz="0 1 0"/>
    </joint>

    <joint name="shoulderLX" type="revolute">
        <parent link="armL_upper"/>
        <child link="armL_upper"/>
        <origin xyz="0 0.2 0.25" rpy="0 0 0"/>
        <axis xyz="1 0 0"/>
    </joint>

    <link name="armL_upper">
        <visual>
            <geometry><box size="0.06 0.06 0.2"/></geometry>
            <origin xyz="0 0 -0.1" rpy="0 0 0"/>
        </visual>
    </link>

    <joint name="armRotatorL" type="revolute">
        <parent link="armL_upper"/>
        <child link="armL_lower"/>
        <origin xyz="0 0 -0.2" rpy="0 0 0"/>
        <axis xyz="0 0 1"/>
    </joint>

    <link name="armL_lower">
        <visual>
            <geometry><box size="0.06 0.06 0.2"/></geometry>
            <origin xyz="0 0 -0.1" rpy="0 0 0"/>
        </visual>
    </link>

    <joint name="elbowL" type="revolute">
        <parent link="armL_lower"/>
        <child link="forearmL"/>
        <origin xyz="0 0 -0.2" rpy="0 0 0"/>
        <axis xyz="0 1 0"/>
    </joint>

    <link name="forearmL">
        <visual>
            <geometry><box size="0.06 0.06 0.3"/></geometry>
            <origin xyz="0 0 -0.15" rpy="0 0 0"/>
        </visual>
    </link>-->

    <!-- Digitigrade -->
    <!-- *Design digitigrade Alexa* -->

    <!-- Left leg -->

</robot>